Training dataset size: 400
Training dataset size: 400
  0%|                                                  | 0/1000 [00:00<?, ?it/s]/home/kebl6872/miniconda3/envs/pytorch_env/lib/python3.10/site-packages/torch/autograd/__init__.py:173: UserWarning: Error detected in ReluBackward0. Traceback of forward call that caused the error:
  File "/home/kebl6872/REFUGE_4YP/Run/PromptUNetTrain.py", line 174, in <module>
    model = prompt_model_pipeline(config)
  File "/home/kebl6872/REFUGE_4YP/Run/PromptUNetTrain.py", line 146, in prompt_model_pipeline
    prompt_train(model,train_loader,test_loader,criterion,eval_criterion,config)
  File "/home/kebl6872/REFUGE_4YP/Run/PromptUNetTrain.py", line 98, in prompt_train
    loss = prompt_train_batch(images,labels,points,point_labels,model,optimizer,criterion)
  File "/home/kebl6872/REFUGE_4YP/Run/PromptUNetTrain.py", line 9, in prompt_train_batch
    outputs = model(images,point_input,point_label_input)
  File "/home/kebl6872/miniconda3/envs/pytorch_env/lib/python3.10/site-packages/torch/nn/modules/module.py", line 1128, in _call_impl
    result = forward_call(*input, **kwargs)
  File "/home/kebl6872/REFUGE_4YP/Run/PromptUNet/PromptUNet.py", line 112, in forward
    b = self.b(p4)
  File "/home/kebl6872/miniconda3/envs/pytorch_env/lib/python3.10/site-packages/torch/nn/modules/module.py", line 1110, in _call_impl
    return forward_call(*input, **kwargs)
  File "/home/kebl6872/REFUGE_4YP/Run/PromptUNet/PromptUNet.py", line 43, in forward
    x = self.relu(x)
  File "/home/kebl6872/miniconda3/envs/pytorch_env/lib/python3.10/site-packages/torch/nn/modules/module.py", line 1110, in _call_impl
    return forward_call(*input, **kwargs)
  File "/home/kebl6872/miniconda3/envs/pytorch_env/lib/python3.10/site-packages/torch/nn/modules/activation.py", line 98, in forward
    return F.relu(input, inplace=self.inplace)
  File "/home/kebl6872/miniconda3/envs/pytorch_env/lib/python3.10/site-packages/torch/nn/functional.py", line 1442, in relu
    result = torch.relu(input)
 (Triggered internally at  /opt/conda/conda-bld/pytorch_1646755897462/work/torch/csrc/autograd/python_anomaly_mode.cpp:104.)
  Variable._execution_engine.run_backward(  # Calls into the C++ engine to run the backward pass
  0%|                                                  | 0/1000 [00:01<?, ?it/s]
Traceback (most recent call last):
  File "/home/kebl6872/REFUGE_4YP/Run/PromptUNetTrain.py", line 146, in prompt_model_pipeline
    prompt_train(model,train_loader,test_loader,criterion,eval_criterion,config)
  File "/home/kebl6872/REFUGE_4YP/Run/PromptUNetTrain.py", line 98, in prompt_train
    loss = prompt_train_batch(images,labels,points,point_labels,model,optimizer,criterion)
  File "/home/kebl6872/REFUGE_4YP/Run/PromptUNetTrain.py", line 12, in prompt_train_batch
    loss.backward()
  File "/home/kebl6872/miniconda3/envs/pytorch_env/lib/python3.10/site-packages/torch/_tensor.py", line 363, in backward
    torch.autograd.backward(self, gradient, retain_graph, create_graph, inputs=inputs)
  File "/home/kebl6872/miniconda3/envs/pytorch_env/lib/python3.10/site-packages/torch/autograd/__init__.py", line 173, in backward
    Variable._execution_engine.run_backward(  # Calls into the C++ engine to run the backward pass
RuntimeError: one of the variables needed for gradient computation has been modified by an inplace operation: [torch.cuda.FloatTensor [8, 384, 32, 32]], which is output 0 of ReluBackward0, is at version 1; expected version 0 instead. Hint: the backtrace further above shows the operation that failed to compute its gradient. The variable in question was changed in there or anywhere later. Good luck!